Workbook

Sheet Data
A1: 1 | B1: Employee cost as a % of Revenue | I1: April | J1: May | K1: June | L1: July | M1: August | N1: September | O1: October | P1: November | Q1: December | R1: January | S1: February | T1: March
B2: Cost of Slaries/ Wages | C2: 85020101 | D2: =C2/C3*100 -> 1.4626253 | E2: =AVERAGE(I2:V2) -> 1.4839539e+08 | F2: =E2/E3*100 -> 6.57876 | H2: Cost of Slaries/ Wages | I2: 125826505 | J2: 26947436 | K2: 51989973 | L2: 18914200 | M2: 52786195 | N2: 31178814 | O2: 82582639 | P2: 53530143 | Q2: 99085507 | R2: 990487786 | S2: 99020101
B3: Revenue ' | C3: 5812842231 | E3: =AVERAGE(I3:V3) -> 2.2556742e+09 | H3: Revenue ' | I3: 7366773256 | J3: 222725559 | K3: 813895469 | L3: 8.9771118e+09 | M3: 8.578575e+08 | N3: 1464492533 | O3: 1272194008 | P3: 791286362 | Q3: 7.9965566e+08 | R3: 1033581573 | S3: 1212842231
I4: =I2/I3 -> 0.017080274 | J4: =J2/J3 -> 0.12098942 | K4: =K2/K3 -> 0.063877949 | L4: =L2/L3 -> 0.002106936 | M4: =M2/M3 -> 0.061532591 | N4: =N2/N3 -> 0.021289842 | O4: =O2/O3 -> 0.064913558 | P4: =P2/P3 -> 0.067649521 | ... T4: =T2/T3 -> #DIV/0!
B6: Emp Cost Groth 2Y CAGR | C6: 0.12
B7: OP Groth 2Y CAGR | C7: 0.18
B8: Revenue Groth 2 Y CAGR | C8: 0.24
H9: HC 24 | I9: 154 | J9: 166 | K9: 171 | L9: =71+100 -> 171 | M9: 172 | N9: 170 | O9: 168 | P9: 168 | Q9: 168 | R9: 167 | S9: 167 | T9: 167 | U9: =AVERAGE(I9:T9) -> 167.41667
A10: 2 | B10: L/ Head | H10: HC 25 | I10: =96+71 -> 167 | J10: 170 | K10: =101+72 -> 173 | L10: =109+71 -> 180 | M10: =117+73 -> 190 | N10: =119+71 -> 190 | O10: 180 | P10: =94+76 -> 170 | Q10: 170 | R10: 174 | S10: =76+97 -> 173 | T10: 174 | U10: =AVERAGE(I10:T10) -> 175.91667
C11: Kgs/Head | I11: April | J11: May | K11: June | L11: July | M11: August | N11: September | O11: October | P11: November | Q11: December | R11: January | S11: February | T11: March | U11: Total
B12: Actual Feb | C12: =R15/R10 -> 10664.414 | H12: L 24 A | I12: 860592 | J12: 4221405 | K12: 2500874 | L12: 2390338 | M12: 3315266 | N12: 1053765 | O12: 1256069 | P12: 995265 | Q12: 1339394 | R12: 1106773 | S12: 1083551 | T12: 904919 | U12: =AVERAGE(I12:T12) -> 1752350.9 | V12: For the year
B13: Actual 25/26 YTM | C13: =U15/U10 -> 8590.0346 | H13: L Budget 25 | I13: 986000 | J13: 1138000 | K13: 1444000 | L13: 1399000 | M13: 1481000 | N13: 894000 | O13: 1460000 | P13: 1929000 | Q13: 1814000 | R13: 1839000 | S13: 1719000 | T13: 1840000 | U13: =AVERAGE(I13:T13) -> 1495250 | V13: =AVERAGE(I18:T18) -> 172.5
B14: Budget 25/26 Y | C14: =U13/V13 -> 8668.1159
B15: Actual 24/25 Y | C15: =U12/U9 -> 10467.004 | H15: L 25 A | I15: 863998 | J15: 1303937 | K15: 1500827 | L15: 1776890 | M15: 1752338 | N15: 1733831 | O15: 1814082 | P15: 1402657 | Q15: 623787 | R15: 1855608 | S15: 1650000 | T15: 1855608 | U15: =AVERAGE(I15:T15) -> 1511130.2
H16: Act pro HC Bud | I16: 78 | J16: 78 | K16: 78 | L16: 78 | M16: 81 | N16: 81 | O16: 81 | P16: 81 | Q16: 81 | R16: 81 | S16: 81 | T16: 81
H17: MP Bd | I17: 96 | J17: 91 | K17: 91 | L17: 96 | M17: 94 | N17: 91 | O17: 91 | P17: 91 | Q17: 91 | R17: 92 | S17: 93 | T17: 93
A18: 3 | B18: Cadre - Manpower | H18: Total | I18: =SUM(I16:I17) -> 174 | J18: =SUM(J16:J17) -> 169 | K18: =SUM(K16:K17) -> 169 | L18: =SUM(L16:L17) -> 174 | M18: =SUM(M16:M17) -> 175 | N18: =SUM(N16:N17) -> 172 | O18: =SUM(O16:O17) -> 172 | P18: =SUM(P16:P17) -> 172 | ... T18: =SUM(T16:T17) -> 174
B19: Column3 | C19: Column4 | D19: Column1 | E19: Column2 | I19: April | J19: May | K19: June | L19: July | M19: August | N19: September | O19: October | P19: November | Q19: December | R19: January | S19: February | T19: March
B20: Budget | C20: 103 | H20: Actual | I20: 96 | J20: 99 | K20: 101 | L20: 109 | M20: =71+23+14+5+3+1 -> 117 | N20: 119 | O20: 107 | P20: =65+6+14+4+5 -> 94 | Q20: 95 | R20: 99 | S20: 97 | T20: 98
B21: Actual | C21: 108 | H21: Budget | I21: 96 | J21: 91 | K21: 91 | L21: 96 | M21: 94 | N21: 91 | O21: 91 | P21: 91 | Q21: 91 | R21: 93 | S21: 93 | T21: 93
B22: YTM | C22: =AVERAGE(I20:T20) -> 102.58333
A24: 4 | B24: Overtime
B25: Month | C25: Budget | D25: Actual | E25: Budget YTM | F25: Actual YTM | I25: April | J25: May | K25: June | L25: July | M25: August | N25: September | O25: October | P25: November | Q25: December | R25: January | S25: February | T25: March
B26: 25/26 YTM | C26: 4.38 | D26: =3040850/1000000 -> 3.04085 | E26: =SUM(I26:T26)/1000000 -> 28.307934 | F26: =SUM(I27:T27)/1000000 -> 31.34618 | H26: Budget | I26: 2325779.9 | J26: 2325779.9 | K26: 2325779.9 | L26: 2325779.9 | M26: 2375601.9 | N26: 2375601.9 | O26: 2375601.9 | P26: 2375601.9 | Q26: 2375601.9 | R26: 2375601.9 | S26: 2375601.9 | T26: 2375601.9
D27: =(D26-C26)/D26 -> -0.44038673 | F27: =(F26-E26)/E26 -> 0.1073284 | H27: Actual | I27: 1716917.2 | J27: 2405275.4 | K27: 2698073.6 | L27: 2748275 | M27: 2684678 | N27: 2608916.6 | O27: 2767405 | P27: 2375925 | Q27: 2548536 | R27: 3124037 | S27: 2627291.1 | T27: 3040850
E29: 2.63
A30: 5 | B30: Cadre CBL | I30: April | J30: May | K30: June | L30: July | M30: August | N30: September | O30: October | P30: November | Q30: December | R30: January | S30: February | T30: March
B31: Budget | C31: 183 | H31: Actual | I31: 149 | J31: 152 | K31: 152 | L31: 149 | M31: 150 | N31: 154 | O31: 158 | P31: 161 | Q31: 161 | R31: 164 | S31: 163 | T31: 162
B32: Actual | C32: 125 | H32: Budget | I32: 162 | J32: 162 | K32: 162 | L32: 162 | M32: 165 | N32: 165 | O32: 165 | P32: 165 | Q32: 166 | R32: 166 | S32: 165 | T32: 165
B33: YTM | C33: =AVERAGE(I31:T31) -> 156.25
A36: 6 | B36: Resignation
C37: Associates | D37: Staff | E37: Exe and above | F37: Avg | G37: % | H37: HC | J37: May | K37: June | L37: July
B38: HC March | C38: 0 | D38: 8 | E38: 3 | F38: =SUM(C38:E38) -> 11 | G38: =F38/H38*100 -> 8.8 | H38: =C32 -> 125
B39: HC YTM | C39: 8 | D39: 21 | E39: =2+1+1+2+1+1+2 -> 10 | F39: =SUM(C39:E39) -> 39 | G39: =F39/H39*100 -> 25 | H39: 156
A41: 7 | B41: August Training Plan | C41: 15 | D41: =C42/C41 -> 0.46666667
B42: August Actual | C42: 7
A45: 8 | B45: Talent Availability
B46: Time to fill (Days) | C46: 45
B47: Cadre fullfilment (97 %) | C47: =163/166*100 -> 98.192771
B48: CR opened for more than 3M | C48: 0
...

Sheet Financials & Productivity
A1: Month | B1: Year | C1: Date | D1: Company | E1: Cluster | F1: Headcount | G1: Revenue | H1: Salary Cost | I1: Overtime Actual | J1: Overtime Budget | K1: Kgs Per Head Actual | L1: Emp Cost as a % of Revenue
A2: April | B2: 2025 | C2: 45748 | D2: A | E2: D | F2: 167 | G2: 7366773256 | H2: 125826505 | I2: 1716917 | J2: 2325780 | K2: 863998 | L2: =IFERROR($H2/$G2,0) -> 0.017080274
A3: May | B3: 2025 | C3: 45778 | D3: A | E3: D | F3: 170 | G3: 222725559 | H3: 26947436 | I3: 2405275 | J3: 2325780 | K3: 1303937 | L3: =IFERROR($H3/$G3,0) -> 0.12098942
A4: June | B4: 2025 | C4: 45809 | D4: A | E4: D | F4: 173 | G4: 813895469 | H4: 51989973 | I4: 2698074 | J4: 2325780 | K4: 1500827 | L4: =IFERROR($H4/$G4,0) -> 0.063877949
A5: July | B5: 2025 | C5: 45839 | D5: A | E5: D | F5: 180 | G5: 8977111823 | H5: 18914200 | I5: 2748275 | J5: 2325780 | K5: 1776890 | L5: =IFERROR($H5/$G5,0) -> 0.002106936
A6: August | B6: 2025 | C6: 45870 | D6: A | E6: D | F6: 190 | G6: 857857500 | H6: 52786195 | I6: 2684678 | J6: 2375602 | K6: 1752338 | L6: =IFERROR($H6/$G6,0) -> 0.061532591
A7: September | B7: 2025 | C7: 45901 | D7: A | E7: D | F7: 190 | G7: 1464492533 | H7: 31178814 | I7: 2608917 | J7: 2375602 | K7: 1733831 | L7: =IFERROR($H7/$G7,0) -> 0.021289842
A8: October | B8: 2025 | C8: 45931 | D8: A | E8: D | F8: 180 | G8: 1272194008 | H8: 82582639 | I8: 2767405 | J8: 2375602 | K8: 1814082 | L8: =IFERROR($H8/$G8,0) -> 0.064913558
A9: November | B9: 2025 | C9: 45962 | D9: A | E9: D | F9: 170 | G9: 791286362 | H9: 53530143 | I9: 2375925 | J9: 2375602 | K9: 1402657 | L9: =IFERROR($H9/$G9,0) -> 0.067649521
A10: December | B10: 2025 | C10: 45992 | D10: A | E10: D | F10: 170 | G10: 799655664 | H10: 99085507 | I10: 2548536 | J10: 2375602 | K10: 623787 | L10: =IFERROR($H10/$G10,0) -> 0.12391022
A11: January | B11: 2026 | C11: 46023 | D11: A | E11: D | F11: 174 | G11: 1033581573 | H11: 990487786 | I11: 3124037 | J11: 2375602 | K11: 1855608 | L11: =IFERROR($H11/$G11,0) -> 0.95830635
A12: February | B12: 2026 | C12: 46054 | D12: A | E12: D | F12: 173 | G12: 1212842231 | H12: 99020101 | I12: 2627291 | J12: 2375602 | K12: 1650000 | L12: =IFERROR($H12/$G12,0) -> 0.081643019
A13: March | B13: 2026 | C13: 46082 | D13: A | E13: D | F13: 174 | I13: 3040850 | J13: 2375602 | K13: 1855608 | L13: =IFERROR($H13/$G13,0) -> 0
A14: April | B14: 2025 | C14: 45748 | D14: B | E14: D | F14: 134 | G14: 5893418605 | H14: 100661204 | I14: 1373534 | J14: 1800000 | K14: 863998 | L14: =IFERROR($H14/$G14,0) -> 0.017080274
A15: May | B15: 2025 | C15: 45778 | D15: B | E15: D | F15: 136 | G15: 178180447 | H15: 21557949 | I15: 1924220 | J15: 1800000 | K15: 1303937 | L15: =IFERROR($H15/$G15,0) -> 0.12098942
A16: June | B16: 2025 | C16: 45809 | D16: B | E16: D | F16: 138 | G16: 651116375 | H16: 41591978 | I16: 2158459 | J16: 1800000 | K16: 1500827 | L16: =IFERROR($H16/$G16,0) -> 0.063877948
A17: July | B17: 2025 | C17: 45839 | D17: B | E17: D | F17: 144 | G17: 7181689458 | H17: 15131360 | I17: 2198620 | J17: 1800000 | K17: 1776890 | L17: =IFERROR($H17/$G17,0) -> 0.002106936
A18: August | B18: 2025 | C18: 45870 | D18: B | E18: D | F18: 152 | G18: 686286000 | H18: 42228956 | I18: 2147742 | J18: 1910000 | K18: 1752338 | L18: =IFERROR($H18/$G18,0) -> 0.061532591
A19: September | B19: 2025 | C19: 45901 | D19: B | E19: D | F19: 152 | G19: 1171594026 | H19: 24943051 | I19: 2087134 | J19: 1910000 | K19: 1733831 | L19: =IFERROR($H19/$G19,0) -> 0.021289841
A20: October | B20: 2025 | C20: 45931 | D20: B | E20: D | F20: 144 | G20: 1017755206 | H20: 66066111 | I20: 2213924 | J20: 1910000 | K20: 1814082 | L20: =IFERROR($H20/$G20,0) -> 0.064913557
A21: November | B21: 2025 | C21: 45962 | D21: B | E21: D | F21: 136 | G21: 633029090 | H21: 42824114 | I21: 1900740 | J21: 1910000 | K21: 1402657 | L21: =IFERROR($H21/$G21,0) -> 0.06764952
A22: December | B22: 2025 | C22: 45992 | D22: B | E22: D | F22: 136 | G22: 639724531 | H22: 79268406 | I22: 2038829 | J22: 1910000 | K22: 623787 | L22: =IFERROR($H22/$G22,0) -> 0.12391022
A23: January | B23: 2026 | C23: 46023 | D23: B | E23: D | F23: 139 | G23: 826686518 | H23: 792390229 | I23: 2499230 | J23: 1910000 | K23: 1855608 | L23: =IFERROR($H23/$G23,0) -> 0.95851355
A24: February | B24: 2026 | C24: 46054 | D24: B | E24: D | F24: 138 | G24: 970273785 | H24: 79216081 | I24: 2101833 | J24: 1910000 | K24: 1650000 | L24: =IFERROR($H24/$G24,0) -> 0.081643019
A25: March | B25: 2026 | C25: 46082 | D25: B | E25: D | F25: 139 | G25: 0 | H25: 0 | I25: 2432680 | J25: 1910000 | K25: 1855608 | L25: =IFERROR($H25/$G25,0) -> 0
... A37: March | B37: 2026 | C37: 46082 | D37: C | E37: D | F37: 104 | G37: 0 | H37: 0 | I37: 1824510 | J37: 1500000 | K37: 1855608 | L37: =IFERROR($H37/$G37,0) -> 0

Sheet Absenteeism
A1: Month | B1: Year | C1: Date | D1: Company | E1: Cluster | F1: Absenteeism Actual % | G1: Absenteeism Budget %
A2: April | B2: =_xlfn.XLOOKUP(A2,'Financials & Productivity'!A:A,'Financials & Productivity'!B:B) -> 2025 | C2: =_xlfn.XLOOKUP(A2,'Financials & Productivity'!A:A,'Financials & Productivity'!C:C) -> 45748 | D2: A | E2: D | F2: 0.01 | G2: 0
A3: May | B3: =_xlfn.XLOOKUP(A3,'Financials & Productivity'!A:A,'Financials & Productivity'!B:B) -> 2025 | C3: =_xlfn.XLOOKUP(A3,'Financials & Productivity'!A:A,'Financials & Productivity'!C:C) -> 45778 | D3: A | E3: D | F3: 0.03 | G3: 0
A4: June | B4: =_xlfn.XLOOKUP(A4,'Financials & Productivity'!A:A,'Financials & Productivity'!B:B) -> 2025 | C4: =_xlfn.XLOOKUP(A4,'Financials & Productivity'!A:A,'Financials & Productivity'!C:C) -> 45809 | D4: A | E4: D | F4: 0.05 | G4: 0
A5: July | B5: =_xlfn.XLOOKUP(A5,'Financials & Productivity'!A:A,'Financials & Productivity'!B:B) -> 2025 | C5: =_xlfn.XLOOKUP(A5,'Financials & Productivity'!A:A,'Financials & Productivity'!C:C) -> 45839 | D5: A | E5: D | F5: 0.05 | G5: 0
A6: August | B6: =_xlfn.XLOOKUP(A6,'Financials & Productivity'!A:A,'Financials & Productivity'!B:B) -> 2025 | C6: =_xlfn.XLOOKUP(A6,'Financials & Productivity'!A:A,'Financials & Productivity'!C:C) -> 45870 | D6: A | E6: D | F6: 0.04 | G6: 0
A7: September | B7: =_xlfn.XLOOKUP(A7,'Financials & Productivity'!A:A,'Financials & Productivity'!B:B) -> 2025 | C7: =_xlfn.XLOOKUP(A7,'Financials & Productivity'!A:A,'Financials & Productivity'!C:C) -> 45901 | D7: A | E7: D | F7: 0.06 | G7: 0
A8: October | B8: =_xlfn.XLOOKUP(A8,'Financials & Productivity'!A:A,'Financials & Productivity'!B:B) -> 2025 | C8: =_xlfn.XLOOKUP(A8,'Financials & Productivity'!A:A,'Financials & Productivity'!C:C) -> 45931 | D8: A | E8: D | F8: 0.08 | G8: 0
A9: November | B9: =_xlfn.XLOOKUP(A9,'Financials & Productivity'!A:A,'Financials & Productivity'!B:B) -> 2025 | C9: =_xlfn.XLOOKUP(A9,'Financials & Productivity'!A:A,'Financials & Productivity'!C:C) -> 45962 | D9: A | E9: D | F9: 0.03 | G9: 0
A10: December | B10: =_xlfn.XLOOKUP(A10,'Financials & Productivity'!A:A,'Financials & Productivity'!B:B) -> 2025 | C10: =_xlfn.XLOOKUP(A10,'Financials & Productivity'!A:A,'Financials & Productivity'!C:C) -> 45992 | D10: A | E10: D | F10: 0.03 | G10: 0
A11: January | B11: =_xlfn.XLOOKUP(A11,'Financials & Productivity'!A:A,'Financials & Productivity'!B:B) -> 2026 | C11: =_xlfn.XLOOKUP(A11,'Financials & Productivity'!A:A,'Financials & Productivity'!C:C) -> 46023 | D11: A | E11: D | F11: 0 | G11: 0
A12: February | B12: =_xlfn.XLOOKUP(A12,'Financials & Productivity'!A:A,'Financials & Productivity'!B:B) -> 2026 | C12: =_xlfn.XLOOKUP(A12,'Financials & Productivity'!A:A,'Financials & Productivity'!C:C) -> 46054 | D12: A | E12: D | F12: 0 | G12: 0
A13: March | B13: =_xlfn.XLOOKUP(A13,'Financials & Productivity'!A:A,'Financials & Productivity'!B:B) -> 2026 | C13: =_xlfn.XLOOKUP(A13,'Financials & Productivity'!A:A,'Financials & Productivity'!C:C) -> 46082 | D13: A | E13: D | F13: 0 | G13: 0
... A37: March | B37: =_xlfn.XLOOKUP(A37,'Financials & Productivity'!A:A,'Financials & Productivity'!B:B) -> 2026 | C37: =_xlfn.XLOOKUP(A37,'Financials & Productivity'!A:A,'Financials & Productivity'!C:C) -> 46082 | D37: C | E37: D | F37: 0 | G37: 0

Sheet Emp Master
A1: Employee ID | B1: Company | C1: Cluster | D1: Department | E1: Gender | F1: Age Band | G1: Employment Type | H1: Performance Rating | I1: Tenure Years | J1: Salary
A2: A001 | B2: A | C2: D | D2: Operations | E2: Male | F2: 25-34 | G2: Permanent | H2: Meets Expectations | I2: 2 | J2: =_xlfn.XLOOKUP(D2,$L$2:$L$5,$M$2:$M$5) -> 35000 | L2: Operations | M2: 35000
A3: A002 | B3: A | C3: D | D3: Operations | E3: Female | F3: 25-34 | G3: Contract | H3: Below Expectations | I3: 1 | J3: =_xlfn.XLOOKUP(D3,$L$2:$L$5,$M$2:$M$5) -> 35000 | L3: Sales | M3: 45000
A4: A003 | B4: A | C4: D | D4: Sales | E4: Male | F4: 35-44 | G4: Permanent | H4: Exceeds Expectations | I4: 5 | J4: =_xlfn.XLOOKUP(D4,$L$2:$L$5,$M$2:$M$5) -> 45000 | L4: Finance | M4: 55000
A5: A004 | B5: A | C5: D | D5: Finance | E5: Female | F5: 45-54 | G5: Permanent | H5: Meets Expectations | I5: 10 | J5: =_xlfn.XLOOKUP(D5,$L$2:$L$5,$M$2:$M$5) -> 55000 | L5: HR | M5: 40000
A6: A005 | B6: A | C6: D | D6: HR | E6: Male | F6: 25-34 | G6: Permanent | H6: Exceeds Expectations | I6: 3 | J6: =_xlfn.XLOOKUP(D6,$L$2:$L$5,$M$2:$M$5) -> 40000
A7: A006 | B7: A | C7: D | D7: Operations | E7: Male | F7: 18-24 | G7: Contract | H7: Meets Expectations | I7: 1 | J7: =_xlfn.XLOOKUP(D7,$L$2:$L$5,$M$2:$M$5) -> 35000
A8: A007 | B8: A | C8: D | D8: Sales | E8: Female | F8: 35-44 | G8: Permanent | H8: Meets Expectations | I8: 4 | J8: =_xlfn.XLOOKUP(D8,$L$2:$L$5,$M$2:$M$5) -> 45000
A9: A008 | B9: A | C9: D | D9: Operations | E9: Male | F9: 25-34 | G9: Permanent | H9: Below Expectations | I9: 2 | J9: =_xlfn.XLOOKUP(D9,$L$2:$L$5,$M$2:$M$5) -> 35000
A10: A009 | B10: A | C10: D | D10: Finance | E10: Male | F10: 45-54 | G10: Permanent | H10: Exceeds Expectations | I10: 8 | J10: =_xlfn.XLOOKUP(D10,$L$2:$L$5,$M$2:$M$5) -> 55000
A11: A010 | B11: A | C11: D | D11: HR | E11: Female | F11: 25-34 | G11: Contract | H11: Meets Expectations | I11: 2 | J11: =_xlfn.XLOOKUP(D11,$L$2:$L$5,$M$2:$M$5) -> 40000
A12: B001 | B12: B | C12: D | D12: Operations | E12: Female | F12: 25-34 | G12: Permanent | H12: Meets Expectations | I12: 4 | J12: =_xlfn.XLOOKUP(D12,$L$2:$L$5,$M$2:$M$5) -> 35000
A13: B002 | B13: B | C13: D | D13: Sales | E13: Male | F13: 35-44 | G13: Contract | H13: Below Expectations | I13: 1 | J13: =_xlfn.XLOOKUP(D13,$L$2:$L$5,$M$2:$M$5) -> 45000
A14: B003 | B14: B | C14: D | D14: HR | E14: Female | F14: 25-34 | G14: Permanent | H14: Exceeds Expectations | I14: 3 | J14: =_xlfn.XLOOKUP(D14,$L$2:$L$5,$M$2:$M$5) -> 40000
A15: B004 | B15: B | C15: D | D15: Operations | E15: Male | F15: 18-24 | G15: Contract | H15: Meets Expectations | I15: 1 | J15: =_xlfn.XLOOKUP(D15,$L$2:$L$5,$M$2:$M$5) -> 35000
A16: B005 | B16: B | C16: D | D16: Finance | E16: Female | F16: 35-44 | G16: Permanent | H16: Meets Expectations | I16: 6 | J16: =_xlfn.XLOOKUP(D16,$L$2:$L$5,$M$2:$M$5) -> 55000
A17: B006 | B17: B | C17: D | D17: Operations | E17: Male | F17: 25-34 | G17: Permanent | H17: Below Expectations | I17: 2 | J17: =_xlfn.XLOOKUP(D17,$L$2:$L$5,$M$2:$M$5) -> 35000
... A25: C006 | B25: C | C25: D | D25: Sales | E25: Male | F25: 25-34 | G25: Contract | H25: Meets Expectations | I25: 1 | J25: =_xlfn.XLOOKUP(D25,$L$2:$L$5,$M$2:$M$5) -> 45000

Sheet HR Metrics
A1: Month | B1: Year | C1: Date | D1: Company | E1: Cluster | F1: Resignations Associates | G1: Resignations Staff | H1: Resignations Exec Above | I1: Total Resignations | J1: Regrettable Resignations | K1: Vacancies Filled | L1: Internal Promotions | M1: PDP Planned | N1: PDP Completed
A2: April | B2: =_xlfn.XLOOKUP(A2,'Financials & Productivity'!A:A,'Financials & Productivity'!B:B) -> 2025 | C2: =_xlfn.XLOOKUP(A2,'Financials & Productivity'!A:A,'Financials & Productivity'!C:C) -> 45748 | D2: A | E2: D | F2: 0 | G2: 2 | H2: 0 | I2: =SUM(F2:H2) -> 2 | J2: 0 | K2: 3 | L2: 1 | M2: 0 | N2: 0
A3: May | B3: =_xlfn.XLOOKUP(A3,'Financials & Productivity'!A:A,'Financials & Productivity'!B:B) -> 2025 | C3: =_xlfn.XLOOKUP(A3,'Financials & Productivity'!A:A,'Financials & Productivity'!C:C) -> 45778 | D3: A | E3: D | F3: 0 | G3: 2 | H3: 1 | I3: =SUM(F3:H3) -> 3 | J3: 0 | K3: 4 | L3: 1 | M3: 0 | N3: 0
A4: June | B4: =_xlfn.XLOOKUP(A4,'Financials & Productivity'!A:A,'Financials & Productivity'!B:B) -> 2025 | C4: =_xlfn.XLOOKUP(A4,'Financials & Productivity'!A:A,'Financials & Productivity'!C:C) -> 45809 | D4: A | E4: D | F4: 1 | G4: 2 | H4: 1 | I4: =SUM(F4:H4) -> 4 | J4: 1 | K4: 5 | L4: 2 | M4: 0 | N4: 0
A5: July | B5: =_xlfn.XLOOKUP(A5,'Financials & Productivity'!A:A,'Financials & Productivity'!B:B) -> 2025 | C5: =_xlfn.XLOOKUP(A5,'Financials & Productivity'!A:A,'Financials & Productivity'!C:C) -> 45839 | D5: A | E5: D | F5: 0 | G5: 2 | H5: 1 | I5: =SUM(F5:H5) -> 3 | J5: 0 | K5: 4 | L5: 1 | M5: 0 | N5: 0
A6: August | B6: =_xlfn.XLOOKUP(A6,'Financials & Productivity'!A:A,'Financials & Productivity'!B:B) -> 2025 | C6: =_xlfn.XLOOKUP(A6,'Financials & Productivity'!A:A,'Financials & Productivity'!C:C) -> 45870 | D6: A | E6: D | F6: 1 | G6: 2 | H6: 1 | I6: =SUM(F6:H6) -> 4 | J6: 0 | K6: 5 | L6: 2 | M6: 25 | N6: 10
A7: September | B7: =_xlfn.XLOOKUP(A7,'Financials & Productivity'!A:A,'Financials & Productivity'!B:B) -> 2025 | C7: =_xlfn.XLOOKUP(A7,'Financials & Productivity'!A:A,'Financials & Productivity'!C:C) -> 45901 | D7: A | E7: D | F7: 1 | G7: 1 | H7: 1 | I7: =SUM(F7:H7) -> 3 | J7: 0 | K7: 4 | L7: 1 | M7: 15 | N7: 3
A8: October | B8: =_xlfn.XLOOKUP(A8,'Financials & Productivity'!A:A,'Financials & Productivity'!B:B) -> 2025 | C8: =_xlfn.XLOOKUP(A8,'Financials & Productivity'!A:A,'Financials & Productivity'!C:C) -> 45931 | D8: A | E8: D | F8: 1 | G8: 1 | H8: 1 | I8: =SUM(F8:H8) -> 3 | J8: 1 | K8: 5 | L8: 2 | M8: 0 | N8: 0
A9: November | B9: =_xlfn.XLOOKUP(A9,'Financials & Productivity'!A:A,'Financials & Productivity'!B:B) -> 2025 | C9: =_xlfn.XLOOKUP(A9,'Financials & Productivity'!A:A,'Financials & Productivity'!C:C) -> 45962 | D9: A | E9: D | F9: 0 | G9: 1 | H9: 0 | I9: =SUM(F9:H9) -> 1 | J9: 0 | K9: 4 | L9: 1 | M9: 35 | N9: 10
A10: December | B10: =_xlfn.XLOOKUP(A10,'Financials & Productivity'!A:A,'Financials & Productivity'!B:B) -> 2025 | C10: =_xlfn.XLOOKUP(A10,'Financials & Productivity'!A:A,'Financials & Productivity'!C:C) -> 45992 | D10: A | E10: D | F10: 0 | G10: 0 | H10: 1 | I10: =SUM(F10:H10) -> 1 | J10: 0 | K10: 4 | L10: 1 | M10: 0 | N10: 0
A11: January | B11: =_xlfn.XLOOKUP(A11,'Financials & Productivity'!A:A,'Financials & Productivity'!B:B) -> 2026 | C11: =_xlfn.XLOOKUP(A11,'Financials & Productivity'!A:A,'Financials & Productivity'!C:C) -> 46023 | D11: A | E11: D | F11: 2 | G11: 0 | H11: 0 | I11: =SUM(F11:H11) -> 2 | J11: 0 | K11: 5 | L11: 2 | M11: 0 | N11: 0
A12: February | B12: =_xlfn.XLOOKUP(A12,'Financials & Productivity'!A:A,'Financials & Productivity'!B:B) -> 2026 | C12: =_xlfn.XLOOKUP(A12,'Financials & Productivity'!A:A,'Financials & Productivity'!C:C) -> 46054 | D12: A | E12: D | F12: 2 | G12: 0 | H12: 0 | I12: =SUM(F12:H12) -> 2 | J12: 0 | K12: 4 | L12: 1 | M12: 0 | N12: 0
A13: March | B13: =_xlfn.XLOOKUP(A13,'Financials & Productivity'!A:A,'Financials & Productivity'!B:B) -> 2026 | C13: =_xlfn.XLOOKUP(A13,'Financials & Productivity'!A:A,'Financials & Productivity'!C:C) -> 46082 | D13: A | E13: D | F13: 0 | G13: 8 | H13: 3 | I13: =SUM(F13:H13) -> 11 | J13: 0 | K13: 3 | L13: 1 | M13: 0 | N13: 0
... A37: March | B37: =_xlfn.XLOOKUP(A37,'Financials & Productivity'!A:A,'Financials & Productivity'!B:B) -> 2026 | C37: =_xlfn.XLOOKUP(A37,'Financials & Productivity'!A:A,'Financials & Productivity'!C:C) -> 46082 | D37: C | E37: D | F37: 0 | G37: 5 | H37: 2 | I37: =SUM(F37:H37) -> 7 | J37: 0 | K37: 2 | L37: 1 | M37: 0 | N37: 0

Sheet KPIs
A1: Month | B1: Year | C1: Date | D1: Company | E1: Cluster | F1: Target Regrettable Loss % | G1: Target PDP % | H1: Target Internal Promo % | I1: Target Absenteeism % | J1: Target Overtime Variance %
A2: April | B2: =_xlfn.XLOOKUP(A2,'Financials & Productivity'!A:A,'Financials & Productivity'!B:B) -> 2025 | C2: =_xlfn.XLOOKUP(A2,'Financials & Productivity'!A:A,'Financials & Productivity'!C:C) -> 45748 | D2: A | E2: D | F2: 0.02 | G2: 0.8 | H2: 0.4 | I2: 0 | J2: 0
A3: May | B3: =_xlfn.XLOOKUP(A3,'Financials & Productivity'!A:A,'Financials & Productivity'!B:B) -> 2025 | C3: =_xlfn.XLOOKUP(A3,'Financials & Productivity'!A:A,'Financials & Productivity'!C:C) -> 45778 | D3: A | E3: D | F3: 0.02 | G3: 0.8 | H3: 0.4 | I3: 0 | J3: 0
A4: June | B4: =_xlfn.XLOOKUP(A4,'Financials & Productivity'!A:A,'Financials & Productivity'!B:B) -> 2025 | C4: =_xlfn.XLOOKUP(A4,'Financials & Productivity'!A:A,'Financials & Productivity'!C:C) -> 45809 | D4: A | E4: D | F4: 0.02 | G4: 0.8 | H4: 0.4 | I4: 0 | J4: 0
A5: July | B5: =_xlfn.XLOOKUP(A5,'Financials & Productivity'!A:A,'Financials & Productivity'!B:B) -> 2025 | C5: =_xlfn.XLOOKUP(A5,'Financials & Productivity'!A:A,'Financials & Productivity'!C:C) -> 45839 | D5: A | E5: D | F5: 0.02 | G5: 0.8 | H5: 0.4 | I5: 0 | J5: 0
A6: August | B6: =_xlfn.XLOOKUP(A6,'Financials & Productivity'!A:A,'Financials & Productivity'!B:B) -> 2025 | C6: =_xlfn.XLOOKUP(A6,'Financials & Productivity'!A:A,'Financials & Productivity'!C:C) -> 45870 | D6: A | E6: D | F6: 0.02 | G6: 0.8 | H6: 0.4 | I6: 0 | J6: 0
A7: September | B7: =_xlfn.XLOOKUP(A7,'Financials & Productivity'!A:A,'Financials & Productivity'!B:B) -> 2025 | C7: =_xlfn.XLOOKUP(A7,'Financials & Productivity'!A:A,'Financials & Productivity'!C:C) -> 45901 | D7: A | E7: D | F7: 0.02 | G7: 0.8 | H7: 0.4 | I7: 0 | J7: 0
A8: October | B8: =_xlfn.XLOOKUP(A8,'Financials & Productivity'!A:A,'Financials & Productivity'!B:B) -> 2025 | C8: =_xlfn.XLOOKUP(A8,'Financials & Productivity'!A:A,'Financials & Productivity'!C:C) -> 45931 | D8: A | E8: D | F8: 0.02 | G8: 0.8 | H8: 0.4 | I8: 0 | J8: 0
A9: November | B9: =_xlfn.XLOOKUP(A9,'Financials & Productivity'!A:A,'Financials & Productivity'!B:B) -> 2025 | C9: =_xlfn.XLOOKUP(A9,'Financials & Productivity'!A:A,'Financials & Productivity'!C:C) -> 45962 | D9: A | E9: D | F9: 0.02 | G9: 0.8 | H9: 0.4 | I9: 0 | J9: 0
A10: December | B10: =_xlfn.XLOOKUP(A10,'Financials & Productivity'!A:A,'Financials & Productivity'!B:B) -> 2025 | C10: =_xlfn.XLOOKUP(A10,'Financials & Productivity'!A:A,'Financials & Productivity'!C:C) -> 45992 | D10: A | E10: D | F10: 0.02 | G10: 0.8 | H10: 0.4 | I10: 0 | J10: 0
A11: January | B11: =_xlfn.XLOOKUP(A11,'Financials & Productivity'!A:A,'Financials & Productivity'!B:B) -> 2026 | C11: =_xlfn.XLOOKUP(A11,'Financials & Productivity'!A:A,'Financials & Productivity'!C:C) -> 46023 | D11: A | E11: D | F11: 0.02 | G11: 0.8 | H11: 0.4 | I11: 0 | J11: 0
A12: February | B12: =_xlfn.XLOOKUP(A12,'Financials & Productivity'!A:A,'Financials & Productivity'!B:B) -> 2026 | C12: =_xlfn.XLOOKUP(A12,'Financials & Productivity'!A:A,'Financials & Productivity'!C:C) -> 46054 | D12: A | E12: D | F12: 0.02 | G12: 0.8 | H12: 0.4 | I12: 0 | J12: 0
A13: March | B13: =_xlfn.XLOOKUP(A13,'Financials & Productivity'!A:A,'Financials & Productivity'!B:B) -> 2026 | C13: =_xlfn.XLOOKUP(A13,'Financials & Productivity'!A:A,'Financials & Productivity'!C:C) -> 46082 | D13: A | E13: D | F13: 0.02 | G13: 0.8 | H13: 0.4 | I13: 0 | J13: 0
... A37: March | B37: =_xlfn.XLOOKUP(A37,'Financials & Productivity'!A:A,'Financials & Productivity'!B:B) -> 2026 | C37: =_xlfn.XLOOKUP(A37,'Financials & Productivity'!A:A,'Financials & Productivity'!C:C) -> 46082 | D37: C | E37: D | F37: 0.02 | G37: 0.8 | H37: 0.4 | I37: 0 | J37: 0
